<!DOCTYPE html>
<html>
<head>
<meta charset="UTF-8">
<title>Unexpected exceptions | Elasticsearch.Net and NEST: the .NET clients [6.x] | Elastic</title>
<meta class="elastic" name="content" content="Unexpected exceptions | Elasticsearch.Net and NEST: the .NET clients [6.x]">

<link rel="home" href="index.html" title="Elasticsearch.Net and NEST: the .NET clients [6.x]"/>
<link rel="up" href="thrown-exceptions.html" title="Exceptions"/>
<link rel="prev" href="thrown-exceptions.html" title="Exceptions"/>
<link rel="next" href="unrecoverable-exceptions.html" title="Unrecoverable exceptions"/>
<meta class="elastic" name="product_version" content="6.x"/>
<meta class="elastic" name="product_name" content="Clients"/>
<meta class="elastic" name="website_area" content="documentation"/>
<meta name="DC.type" content="Learn/Docs/Clients/.Net/6.x"/>
<meta name="DC.subject" content="Clients"/>
<meta name="DC.identifier" content="6.x"/>
</head>
<body>
<div class="page_header">
<p>
  <strong>NOTE</strong>: You are looking at documentation for an older release. 
  For the latest information, see the 
  <a href="../current/index.html">current release documentation</a>. 
</p>
</div>
<div class="navheader">
<span class="prev">
<a href="thrown-exceptions.html">« Exceptions</a>
</span>
<span class="next">
<a href="unrecoverable-exceptions.html">Unrecoverable exceptions »</a>
</span>
</div>
<div class="book" lang="en">
<div class="titlepage">
<div class="breadcrumbs">
<span class="breadcrumb-link"><a href="/guide/">Elastic Docs</a></span>
<span class="chevron-right">›</span><span class="breadcrumb-link"><a href="index.html">Elasticsearch.Net and NEST:  the .NET clients [6.x]</a></span>
<span class="chevron-right">›</span><span class="breadcrumb-link"><a href="api-conventions.html">API Conventions</a></span>
<span class="chevron-right">›</span><span class="breadcrumb-link"><a href="thrown-exceptions.html">Exceptions</a></span>
</div>
<div>
<div><h1 class="title"><a id="id-1"></a>Unexpected exceptions</h1><a class="edit_me" rel="nofollow" title="Edit this page on GitHub" href="https://github.com/elastic/elasticsearch-net/edit/6.x/docs/client-concepts/connection-pooling/exceptions/unexpected-exceptions.asciidoc">edit</a></div>
</div>
<!--EXTRA-->
</div>
<div id="content">
<div class="section">
<div class="titlepage"><div><div>
<h2 class="title"><a id="unexpected-exceptions"></a>Unexpected exceptions<a class="edit_me" rel="nofollow" title="Edit this page on GitHub" href="https://github.com/elastic/elasticsearch-net/edit/6.x/docs/client-concepts/connection-pooling/exceptions/unexpected-exceptions.asciidoc">edit</a></h2>
</div></div></div>
<p>When a client call throws an exception that the <code class="literal">IConnection</code> cannot handle, the exception will bubble
out of the client as an <code class="literal">UnexpectedElasticsearchClientException</code>, regardless of whether the client is configured to
throw exceptions or not.</p>
<p>An <code class="literal">IConnection</code> is in charge of knowing which exceptions it can recover from and those it can&#8217;t, and the default <code class="literal">IConnection</code>
in</p>
<div class="ulist itemizedlist">
<ul class="itemizedlist">
<li class="listitem">
Desktop CLR is based on <code class="literal">WebRequest</code> which can and will recover from <code class="literal">WebException</code>
</li>
<li class="listitem">
Core CLR is based on <code class="literal">HttpClient</code> which can and will recover from <code class="literal">HttpRequestException</code>
</li>
</ul>
</div>
<p>Other exceptions will be grounds for immediately exiting the pipeline. Let&#8217;s demonstrate this
using our Virtual cluster test framework</p>
<div class="pre_wrapper lang-csharp">
<div class="console_code_copy" title="Copy to clipboard"></div>
<pre class="programlisting prettyprint lang-csharp">var audit = new Auditor(() =&gt; Framework.Cluster <a id="CO2-1"></a><i class="conum" data-value="1"></i>
    .Nodes(10)
    .ClientCalls(r =&gt; r.SucceedAlways())
    .ClientCalls(r =&gt; r.OnPort(9201).FailAlways(new Exception("boom!"))) <a id="CO2-2"></a><i class="conum" data-value="2"></i>
    .StaticConnectionPool()
    .Settings(s =&gt; s.DisablePing())
);

audit = await audit.TraceCall(
    new ClientCall {
        { AuditEvent.HealthyResponse, 9200 }, <a id="CO2-3"></a><i class="conum" data-value="3"></i>
    }
);

audit = await audit.TraceUnexpectedException(
    new ClientCall {
        { AuditEvent.BadResponse, 9201 }, <a id="CO2-4"></a><i class="conum" data-value="4"></i>
    },
    (e) =&gt;
    {
        e.FailureReason.Should().Be(PipelineFailure.Unexpected);
        e.InnerException.Should().NotBeNull();
        e.InnerException.Message.Should().Be("boom!");
    }
);</pre>
</div>
<div class="calloutlist">
<table border="0" summary="Callout list">
<tr>
<td align="left" valign="top" width="5%">
<p><a href="#CO2-1"><i class="conum" data-value="1"></i></a></p>
</td>
<td align="left" valign="top">
<p>set up a cluster with 10 nodes</p>
</td>
</tr>
<tr>
<td align="left" valign="top" width="5%">
<p><a href="#CO2-2"><i class="conum" data-value="2"></i></a></p>
</td>
<td align="left" valign="top">
<p>where node 2 on port 9201 always throws an exception</p>
</td>
</tr>
<tr>
<td align="left" valign="top" width="5%">
<p><a href="#CO2-3"><i class="conum" data-value="3"></i></a></p>
</td>
<td align="left" valign="top">
<p>The first call to 9200 returns a healthy response</p>
</td>
</tr>
<tr>
<td align="left" valign="top" width="5%">
<p><a href="#CO2-4"><i class="conum" data-value="4"></i></a></p>
</td>
<td align="left" valign="top">
<p>&#8230;&#8203;but the second call, to 9201, returns a bad response</p>
</td>
</tr>
</table>
</div>
<p>Sometimes, an unexpected exception happens further down in the pipeline. In this scenario, we
wrap them inside an <code class="literal">UnexpectedElasticsearchClientException</code> so that information about where
in the pipeline the exception happened is not lost.</p>
<p>In this next example, a call to 9200 fails with a <code class="literal">WebException</code>.
The call then rolls over to retry on 9201, which throws an hard exception from within <code class="literal">IConnection</code>.
Finally, we assert that we can still see the audit trail for the whole coordinated request.</p>
<div class="pre_wrapper lang-csharp">
<div class="console_code_copy" title="Copy to clipboard"></div>
<pre class="programlisting prettyprint lang-csharp">var audit = new Auditor(() =&gt; Framework.Cluster
    .Nodes(10)
#if DOTNETCORE
    .ClientCalls(r =&gt; r.OnPort(9200).FailAlways(new System.Net.Http.HttpRequestException("recover")))
#else
    .ClientCalls(r =&gt; r.OnPort(9200).FailAlways(new WebException("recover"))) <a id="CO3-1"></a><i class="conum" data-value="1"></i>
#endif
    .ClientCalls(r =&gt; r.OnPort(9201).FailAlways(new Exception("boom!"))) <a id="CO3-2"></a><i class="conum" data-value="2"></i>
    .StaticConnectionPool()
    .Settings(s =&gt; s.DisablePing())
);

audit = await audit.TraceUnexpectedException(
    new ClientCall {
        { AuditEvent.BadResponse, 9200 },
        { AuditEvent.BadResponse, 9201 }, <a id="CO3-3"></a><i class="conum" data-value="3"></i>
    },
    (e) =&gt;
    {
        e.FailureReason.Should().Be(PipelineFailure.Unexpected);
        e.InnerException.Should().NotBeNull();
        e.InnerException.Message.Should().Be("boom!");
    }
);</pre>
</div>
<div class="calloutlist">
<table border="0" summary="Callout list">
<tr>
<td align="left" valign="top" width="5%">
<p><a href="#CO3-1"><i class="conum" data-value="1"></i></a></p>
</td>
<td align="left" valign="top">
<p>calls on 9200 set up to throw a <code class="literal">WebException</code></p>
</td>
</tr>
<tr>
<td align="left" valign="top" width="5%">
<p><a href="#CO3-2"><i class="conum" data-value="2"></i></a></p>
</td>
<td align="left" valign="top">
<p>calls on 9201 set up to throw an <code class="literal">Exception</code></p>
</td>
</tr>
<tr>
<td align="left" valign="top" width="5%">
<p><a href="#CO3-3"><i class="conum" data-value="3"></i></a></p>
</td>
<td align="left" valign="top">
<p>Assert that the audit trail for the client call includes the bad response from 9200 and 9201</p>
</td>
</tr>
</table>
</div>
<p>An unexpected hard exception on ping and sniff is something we <span class="strong strong"><strong>do</strong></span> try to recover from and failover to retrying on the next node.</p>
<p>Here, pinging nodes on first use is enabled and the node on port 9200 throws an exception on ping; when this happens,
we still fallover to retry the ping on node on port 9201, where it succeeds.
Following this, the client call on 9201 throws a hard exception that we are not able to recover from</p>
<div class="pre_wrapper lang-csharp">
<div class="console_code_copy" title="Copy to clipboard"></div>
<pre class="programlisting prettyprint lang-csharp">var audit = new Auditor(() =&gt; Framework.Cluster
    .Nodes(10)
    .Ping(r =&gt; r.OnPort(9200).FailAlways(new Exception("ping exception")))
    .Ping(r =&gt; r.OnPort(9201).SucceedAlways())
    .ClientCalls(r =&gt; r.OnPort(9201).FailAlways(new Exception("boom!")))
    .StaticConnectionPool()
    .AllDefaults()
);

audit = await audit.TraceUnexpectedException(
    new ClientCall {
        { AuditEvent.PingFailure, 9200 },
        { AuditEvent.PingSuccess, 9201 },
        { AuditEvent.BadResponse, 9201 },
    },
    e =&gt;
    {
        e.FailureReason.Should().Be(PipelineFailure.Unexpected);

        e.InnerException.Should().NotBeNull();
        e.InnerException.Message.Should().Be("boom!"); <a id="CO4-1"></a><i class="conum" data-value="1"></i>

        e.SeenExceptions.Should().NotBeEmpty(); <a id="CO4-2"></a><i class="conum" data-value="2"></i>
        var pipelineException = e.SeenExceptions.First();
        pipelineException.FailureReason.Should().Be(PipelineFailure.PingFailure);
        pipelineException.InnerException.Message.Should().Be("ping exception");

        var pingException = e.AuditTrail.First(a =&gt; a.Event == AuditEvent.PingFailure).Exception; <a id="CO4-3"></a><i class="conum" data-value="3"></i>
        pingException.Should().NotBeNull();
        pingException.Message.Should().Be("ping exception");
    }
);</pre>
</div>
<div class="calloutlist">
<table border="0" summary="Callout list">
<tr>
<td align="left" valign="top" width="5%">
<p><a href="#CO4-1"><i class="conum" data-value="1"></i></a></p>
</td>
<td align="left" valign="top">
<p><code class="literal">InnerException</code> is the exception that brought the request down</p>
</td>
</tr>
<tr>
<td align="left" valign="top" width="5%">
<p><a href="#CO4-2"><i class="conum" data-value="2"></i></a></p>
</td>
<td align="left" valign="top">
<p>The hard exception that happened on ping is still available though</p>
</td>
</tr>
<tr>
<td align="left" valign="top" width="5%">
<p><a href="#CO4-3"><i class="conum" data-value="3"></i></a></p>
</td>
<td align="left" valign="top">
<p>An exception can be hard to relate back to a point in time, so the exception is also available on the audit trail</p>
</td>
</tr>
</table>
</div>
</div>
</div>
</div><div class="navfooter">
<span class="prev">
<a href="thrown-exceptions.html">« Exceptions</a>
</span>
<span class="next">
<a href="unrecoverable-exceptions.html">Unrecoverable exceptions »</a>
</span>
</div>
</body>
</html>
